<mujoco model="common-rig-h">
    <!--  
            Robot Intelligence Lab
            Common Rig (Custom Humanoid) model
            
            @ Contact us : taemoon-jeong (motor_moon94@korea.ac.kr)
    -->
    <compiler coordinate="local" inertiafromgeom="true" angle="radian"/>

    <default>
        <joint limited="true" damping="1" armature="0"/>
        <!-- <geom condim="1" material="matgeom"/> -->
        <geom contype="1" condim="3" margin="0.001" solref=".02 1" solimp=".8 .8 .01" material="matgeom"/>
        <motor ctrlrange="-.4 .4" ctrllimited="true"/>

        <default class="hand"> 
        	<joint limited="true"/>
            <position ctrllimited="true" kp="1"/>
		</default>
    </default>

    <option timestep="0.005" iterations="50" tolerance="1e-10" solver="Newton" jacobian="dense" cone="pyramidal"/>
    <size nconmax="50" njmax="200" nstack="10000"/>

    <visual>
        <map force="0.1" zfar="30"/>
        <rgba haze="0.15 0.25 0.35 1"/>
        <quality shadowsize="2048"/>
        <global offwidth="800" offheight="800"/>
    </visual>

    <asset>
        <texture name="texgeom" type="cube" builtin="flat" mark="cross" width="127" height="1278" 
            rgb1="0.8 0.6 0.4" rgb2="0.8 0.6 0.4" markrgb="1 1 1" random="0.01"/>  
        <material name="matgeom" texture="texgeom" texuniform="true" rgba="0.8 0.6 0.4 1.0"/>
    </asset>

    <worldbody>
        
        <body name="base" pos="0 0 0.960348">
            <freejoint name="base"/>
            <geom name="base" type="sphere" pos="0 0 0" size="0.06"/>
            <body name="torso" pos="0 0 0" euler="0 0 0">
                <geom name="root2spine" type="capsule" fromto="0 0 0 0.00194939 0 0.2017038"  size="0.035" density="2226"/>
                <joint name="root1" type="hinge" pos="0 0 0" axis="1 0 0" range="-0.872222 0.872222" damping="60" stiffness="600" armature="0.02" />
                <joint name="root2" type="hinge" pos="0 0 0" axis="0 1 0" range="-0.523333 2.616667" damping="60" stiffness="600" armature="0.02" />
                <joint name="root3" type="hinge" pos="0 0 0" axis="0 0 1" range="-1.395556 1.395556" damping="60" stiffness="600" armature="0.02" />
                <body name="spine" pos="0.00194939 0 0.2017038" euler="0 0 0">
                    <geom name="spine2neck" type="capsule" fromto="0 0 0 0 0 0.2263381"  size="0.035" density="2226"/>
                    <joint name="spine" type="hinge" pos="0 0 0" axis="0 1 0" range="-0.436111 0.785" damping="60" stiffness="600" armature="0.02" />
                    <joint name="spinex" type="hinge" pos="0 0 0" axis="1 0 0" range="-0.436111 0.785" damping="60" stiffness="600" armature="0.02"/>
                    <joint name="spinez" type="hinge" pos="0 0 0" axis="0 0 1" range="-0.436111 0.785" damping="60" stiffness="600" armature="0.02"/>
                    <body name="neck" pos="0 0 0.2263381" euler="0 0 0">
                        <geom name="neck2rclavicle" type="capsule" fromto="0 0 0 -0.0182683 -0.0119726 0.0730251"  size="0.035"/>
                        <geom name="neck2lclavicle" type="capsule" fromto="0 0 0 -0.0182683 0.0119726 0.0730251"  size="0.035"/>
                        <geom name="neck2head" type="capsule" fromto="0 0 0 0 0 0.1817364"  size="0.035"/>
                        <body name="right_clavicle" pos="-0.0182683 -0.0119726 0.0730251" euler="0 0 0">
                            <geom name="rclavicle2rshoulder" type="capsule" fromto="0 0 0 0 -0.155151 0"  size="0.035"/>
                            <joint name="rc" type="hinge" pos="0 0 0" axis="1 0 0" range="-0.261793 0.261793" damping="60" stiffness="600" armature="0.02"/>
                            <body name="right_shoulder" pos="0 -0.155151 0" euler="0 0 0">
                                <geom name="rshoulder2relbow" type="capsule" fromto="0 0 0 0 -0.291422 0"  size="0.035"/>
                                <joint name="rs1" type="hinge" pos="0 0 0" axis="1 0 0" range="-2.006111 2.006111" stiffness="200" damping="20" armature="0.0068" />
                                <joint name="rs2" type="hinge" pos="0 0 0" axis="0 0 1" range="-1.57 3.141592" stiffness="200" damping="20" armature="0.0051" />
                                <joint name="rs3" type="hinge" pos="0 0 0" axis="0 1 0" range="-3.141592 3.141592" stiffness="200" damping="20" armature="0.0051"/>
                                <body name="right_elbow" pos="0 -0.2768 0" euler="0 0 0">
                                    <geom name="relbow2rwrist" type="capsule" fromto="0 0 0 0 -0.270311 0"  size="0.035"/>
                                    <joint name="re" type="hinge" pos="0 0 0" axis="0 0 1" range="0.01 2.61666666667" stiffness="150" damping="15" armature="0.0028"/>
                                    <body name="right_wrist" pos="0 -0.270311 0" euler="0 0 0">
                                        <geom name="rhand2rmetatwo" type="capsule" fromto="0 0 0 0.0227850 -0.0363963 0.0030774" size="0.0075"/>
                                        <geom name="rhand2rmetathree" type="capsule" fromto="0 0 0 0.0043230 -0.0354591 0.0053477" size="0.0075"/>
                                        <geom name="rhand2rmetafour" type="capsule" fromto="0 0 0 -0.0121556 -0.0357189 0.0033833" size="0.0075"/>
                                        <geom name="rhand2rmetafive" type="capsule" fromto="0 0 0 -0.023199 -0.0339833 -0.0007049" size="0.0075"/>
                                        <joint name="rw1" type="hinge" pos="0 0 0" axis="0 1 0" range="-3.141592 3.141592" damping="5" stiffness="50" armature="0.02"/>
                                        <joint name="rw2" type="hinge" pos="0 0 0" axis="0 0 1" range="-3.141592 3.141592" damping="5" stiffness="50" armature="0.02"/>
                                        <joint name="rw3" type="hinge" pos="0 0 0" axis="1 0 0" range="-3.141592 3.141592" damping="5" stiffness="50" armature="0.02"/>
                                        <body name="rh_meta_2" pos="0.0227850 -0.0363963 0.0030774" euler="0 0 0">
                                            <geom name="rmetatwo2rproxtwo" type="capsule" fromto="0 0 0 0 -0.0605478 0" size="0.0075"/>
                                            <joint name="rh_2_meta" type="hinge" pos="0 0 0" axis="1 0 0" range="0.01 1.570796" damping="5" stiffness="50" armature="0.02"/>
                                                <body name="rh_prox_2" pos="0 -0.0605478 0" euler="0 0 0">
                                                    <geom name="rproxtwo2rmedtwo" type="capsule" fromto="0 0 0 0 -0.0420938 0" size="0.0075"/>
                                                    <joint name="rh_2_prox" type="hinge" pos="0 0 0" axis="1 0 0" range="0.01 1.570796" damping="5" stiffness="50" armature="0.02"/>
                                                        <body name="rh_med_2" pos="0 -0.0420938 0" euler="0 0 0">
                                                            <geom name="rmedtwo2rdisttwo" type="capsule" fromto="0 0 0 0 -0.0261978 0" size="0.0075"/>
                                                            <joint name="rh_2_med" type="hinge" pos="0 0 0" axis="1 0 0" range="0.01 1.570796" damping="5" stiffness="50" armature="0.02"/> 
                                                                <body name="rh_dist_2" pos="0 -0.0261978 0" euler="0 0 0"/>
                                                        </body>
                                                </body>
                                        </body>
                                        <body name="rh_abd_2" pos="0.0227850 -0.0363963 0.0030774" euler="0 0 0">                                            
                                            <joint name="rh_2_abd" type="hinge" pos="0 0 0" axis="0 1 0" range="0.01 1.570796" damping="5" stiffness="50" armature="0.02"/>
                                                <geom name="rmetatwo2rmetaone" type="capsule" fromto="0 0 0 0.023986 0 0" size="0.0075"/>
                                                <body name="rh_meta_1" pos="0.023986 0 0" euler="0 0 0.523599">
                                                    <geom name="rmetaone2rproxone" type="capsule" fromto="0 0 0 0 -0.0472361 0" size="0.0075"/>
                                                    <!-- <joint name="rh_1_abd" type="hinge" pos="0 0 0" axis="0 1 0" range="-0.785398 0.785398" damping="5" stiffness="50" armature="0.02"/> -->
                                                    <joint name="rh_1_meta" type="hinge" pos="0 0 0" axis="0 0 1" range="-1.570796 -0.01" damping="5" stiffness="50" armature="0.02"/>
                                                        <body name="rh_prox_1" pos="0 -0.0472361 0" euler="0 0 0">
                                                            <geom name="rproxone2rdistone" type="capsule" fromto="0 0 0 0 -0.0310265 0" size="0.0075"/>
                                                            <joint name="rh_1_prox" type="hinge" pos="0 0 0" axis="0 0 1" range="-1.047197 -0.01" damping="5" stiffness="50" armature="0.02"/>
                                                                <body name="rh_dist_1" pos="0 -0.0310265 0" euler="0 0 0"/>
                                                        </body>
                                                </body>
                                        </body>
                                        <body name="rh_meta_3" pos="0.0043230 -0.0354591 0.0053477" euler="0 0 0">
                                            <geom name="rmetathree2rproxthree" type="capsule" fromto="0 0 0 0 -0.0599018 0" size="0.0075"/>
                                            <joint name="rh_3_meta" type="hinge" pos="0 0 0" axis="1 0 0" range="0.01 1.570796" damping="5" stiffness="50" armature="0.02"/>
                                                <body name="rh_prox_3" pos="0 -0.0599018 0" euler="0 0 0">
                                                    <geom name="rproxthree2rmedthree" type="capsule" fromto="0 0 0 0 -0.0507048 0" size="0.0075"/>
                                                    <joint name="rh_3_prox" type="hinge" pos="0 0 0" axis="1 0 0" range="0.01 1.570796" damping="5" stiffness="50" armature="0.02"/>
                                                        <body name="rh_med_3" pos="0 -0.0507048 0" euler="0 0 0">
                                                            <geom name="rmedthree2rdistthree" type="capsule" fromto="0 0 0 0 -0.0275057 0" size="0.0075"/>
                                                            <joint name="rh_3_med" type="hinge" pos="0 0 0" axis="1 0 0" range="0.01 1.570796" damping="5" stiffness="50" armature="0.02"/> 
                                                                <body name="rh_dist_3" pos="0 -0.0275057 0" euler="0 0 0"/>
                                                        </body>
                                                </body>
                                        </body>
                                        <body name="rh_meta_4" pos="-0.0121556 -0.0357189 0.0033833" euler="0 0 0">
                                            <geom name="rmetafour2rproxfour" type="capsule" fromto="0 0 0 0 -0.0578554 0" size="0.0075"/>
                                            <joint name="rh_4_meta" type="hinge" pos="0 0 0" axis="1 0 0" range="0.01 1.570796" damping="5" stiffness="50" armature="0.02"/>
                                                <body name="rh_prox_4" pos="0 -0.0578554 0" euler="0 0 0">
                                                    <geom name="rproxfour2rmedfour" type="capsule" fromto="0 0 0 0 -0.0495246 0" size="0.0075"/>
                                                    <joint name="rh_4_prox" type="hinge" pos="0 0 0" axis="1 0 0" range="0.01 1.570796" damping="5" stiffness="50" armature="0.02"/>
                                                        <body name="rh_med_4" pos="0 -0.0495246 0" euler="0 0 0">
                                                            <geom name="rmedfour2rdistfour" type="capsule" fromto="0 0 0 0 -0.0226809 0" size="0.0075"/>
                                                            <joint name="rh_4_med" type="hinge" pos="0 0 0" axis="1 0 0" range="0.01 1.570796" damping="5" stiffness="50" armature="0.02"/> 
                                                                <body name="rh_dist_4" pos="0 -0.0226809 0" euler="0 0 0"/>
                                                        </body>
                                                </body>
                                        </body>
                                        <body name="rh_meta_5" pos="-0.023199 -0.0339833 -0.0007049" euler="0 0 0">
                                            <geom name="rmetafive2rproxfive" type="capsule" fromto="0 0 0 0 -0.0542941 0" size="0.0075 "/>
                                            <joint name="rh_5_meta" type="hinge" pos="0 0 0" axis="1 0 0" range="0.01 1.570796" damping="5" stiffness="50" armature="0.02"/>
                                                <body name="rh_prox_5" pos="0 -0.0542941 0" euler="0 0 0">
                                                    <geom name="rproxfive2rmedfive" type="capsule" fromto="0 0 0 0 -0.0350421 0" size="0.0075"/>
                                                    <joint name="rh_5_prox" type="hinge" pos="0 0 0" axis="1 0 0" range="0.01 1.570796" damping="5" stiffness="50" armature="0.02"/>
                                                        <body name="rh_med_5" pos="0 -0.0350421 0" euler="0 0 0">
                                                            <geom name="rmedfive2rdistfive" type="capsule" fromto="0 0 0 0 -0.0211006 0" size="0.0075"/>
                                                            <joint name="rh_5_med" type="hinge" pos="0 0 0" axis="1 0 0" range="0.01 1.570796" damping="5" stiffness="50" armature="0.02"/> 
                                                                <body name="rh_dist_5" pos="0 -0.0211006 0" euler="0 0 0"/>
                                                        </body>
                                                </body>
                                        </body>
                                    </body>
                                </body>
                            </body>
                        </body>
                        <body name="left_clavicle" pos="-0.0182683 0.0119726 0.0730251" euler="0 0 0">
                            <geom name="lclavicle2lshoulder" type="capsule" fromto="0 0 0 0 0.155151 0"  size="0.035"/>
                            <joint name="lc" type="hinge" pos="0 0 0" axis="1 0 0" range="-0.261793 0.261793" damping="60" stiffness="600" armature="0.02"/>
                            <body name="left_shoulder" pos="0 0.155151 0" euler="0 0 0">
                                <geom name="lshoulder2lelbow" type="capsule" fromto="0 0 0 0 0.291422 0"  size="0.035" />
                                <joint name="ls1" type="hinge" pos="0 0 0" axis="1 0 0" range="-2.006111 2.006111" stiffness="200" damping="20" armature="0.0068" />
                                <joint name="ls2" type="hinge" pos="0 0 0" axis="0 0 1" range="-3.141592 1.57" stiffness="200" damping="20" armature="0.0051" />
                                <joint name="ls3" type="hinge" pos="0 0 0" axis="0 1 0" range="-3.141592 3.141592" stiffness="200" damping="20" armature="0.0051" />
                                <body name="left_elbow" pos="0 0.291422 0" euler="0 0 0">
                                    <geom name="lelbow2lwrist" type="capsule" fromto="0 0 0 0 0.270311 0"  size="0.035" />
                                    <joint name="le" type="hinge" pos="0 0 0" axis="0 0 1" range="-2.61666666667 -0.01" stiffness="150" damping="15" armature="0.0028" />
                                    <body name="left_wrist" pos="0 0.270311 0" euler="0 0 0">
                                        <geom name="lhand2lmetatwo" type="capsule" fromto="0 0 0 0.0227850 0.0363963 0.0030774" size="0.0075"/>
                                        <geom name="lhand2lmetathree" type="capsule" fromto="0 0 0 0.0043230 0.0354591 0.0053477" size="0.0075"/>
                                        <geom name="lhand2lmetafour" type="capsule" fromto="0 0 0 -0.0121556 0.0357189 0.0033833" size="0.0075"/>
                                        <geom name="lhand2lmetafive" type="capsule" fromto="0 0 0 -0.023199 0.0339833 -0.0007049" size="0.0075"/>
                                        <joint name="lw1" type="hinge" pos="0 0 0" axis="0 1 0" range="-3.141592 3.141592" damping="5" stiffness="50" armature="0.02" />
                                        <joint name="lw2" type="hinge" pos="0 0 0" axis="0 0 1" range="-3.141592 3.141592" damping="5" stiffness="50" armature="0.02" />
                                        <joint name="lw3" type="hinge" pos="0 0 0" axis="1 0 0" range="-3.141592 3.141592" damping="5" stiffness="50" armature="0.02" />
                                        <body name="lh_meta_2" pos="0.0227850 0.0363963 0.0030774" euler="0 0 0">
                                            <geom name="lmetatwo2lproxtwo" type="capsule" fromto="0 0 0 0 0.0605478 0" size="0.0075"/>
                                            <joint name="lh_2_meta" type="hinge" pos="0 0 0" axis="1 0 0" range="-1.570796 -0.01" damping="5" stiffness="50" armature="0.02"/>
                                                <body name="lh_prox_2" pos="0 0.0605478 0" euler="0 0 0">
                                                    <geom name="lproxtwo2lmedtwo" type="capsule" fromto="0 0 0 0 0.0420938 0" size="0.0075"/>
                                                    <joint name="lh_2_prox" type="hinge" pos="0 0 0" axis="1 0 0" range="-1.570796 -0.01" damping="5" stiffness="50" armature="0.02"/>
                                                        <body name="lh_med_2" pos="0 0.0420938 0" euler="0 0 0">
                                                            <geom name="lmedtwo2ldisttwo" type="capsule" fromto="0 0 0 0 0.0261978 0" size="0.0075"/>
                                                            <joint name="lh_2_med" type="hinge" pos="0 0 0" axis="1 0 0" range="-1.570796 -0.01" damping="5" stiffness="50" armature="0.02"/> 
                                                                <body name="lh_dist_2" pos="0 0.0261978 0" euler="0 0 0"/>
                                                        </body>
                                                </body>
                                        </body>
                                        <body name="lh_abd_2" pos="0.0227850 0.0363963 0.0030774" euler="0 0 0">
                                            <joint name="lh_2_abd" type="hinge" pos="0 0 0" axis="0 1 0" range="0.01 1.570796" damping="5" stiffness="50" armature="0.02"/>
                                                <geom name="lmetatwo2lmetaone" type="capsule" fromto="0 0 0 0.023986 0 0" size="0.0075"/>
                                                <body name="lh_meta_1" pos="0.023986 0 0" euler="0 0 -0.523599">
                                                    <geom name="lmetaone2lproxone" type="capsule" fromto="0 0 0 0 0.0472361 0" size="0.0075"/>
                                                    <!-- <joint name="lh_1_abd" type="hinge" pos="0 0 0" axis="0 0 1" range="-0.785398 0.785398" damping="5" stiffness="50" armature="0.02"/> -->
                                                    <joint name="lh_1_meta" type="hinge" pos="0 0 0" axis="0 0 1" range="0.01 1.570796" damping="5" stiffness="50" armature="0.02"/>
                                                        <body name="lh_prox_1" pos="0 0.0472361 0" euler="0 0 0">
                                                            <geom name="lproxone2ldistone" type="capsule" fromto="0 0 0 0 0.0310265 0" size="0.0075"/>
                                                            <joint name="lh_1_prox" type="hinge" pos="0 0 0" axis="0 0 1" range="0.01 1.047197" damping="5" stiffness="50" armature="0.02"/>
                                                                <body name="lh_dist_1" pos="0 0.0310265 0" euler="0 0 0"/>
                                                        </body>
                                                </body>
                                        </body>
                                        <body name="lh_meta_3" pos="0.0043230 0.0354591 0.0053477" euler="0 0 0">
                                            <geom name="lmetathree2lproxthree" type="capsule" fromto="0 0 0 0 0.0599018 0" size="0.0075"/>
                                            <joint name="lh_3_meta" type="hinge" pos="0 0 0" axis="1 0 0" range="-1.570796 -0.01" damping="5" stiffness="50" armature="0.02"/>
                                                <body name="lh_prox_3" pos="0 0.0599018 0" euler="0 0 0">
                                                    <geom name="lproxthree2lmedthree" type="capsule" fromto="0 0 0 0 0.0507048 0" size="0.0075"/>
                                                    <joint name="lh_3_prox" type="hinge" pos="0 0 0" axis="1 0 0" range="-1.570796 -0.01" damping="5" stiffness="50" armature="0.02"/>
                                                        <body name="lh_med_3" pos="0 0.0507048 0" euler="0 0 0">
                                                            <geom name="lmedthree2ldistthree" type="capsule" fromto="0 0 0 0 0.0275057 0" size="0.0075"/>
                                                            <joint name="lh_3_med" type="hinge" pos="0 0 0" axis="1 0 0" range="-1.570796 -0.01" damping="5" stiffness="50" armature="0.02"/> 
                                                                <body name="lh_dist_3" pos="0 0.0275057 0" euler="0 0 0"/>
                                                        </body>
                                                </body>
                                        </body>
                                        <body name="lh_meta_4" pos="-0.0121556 0.0357189 0.0033833" euler="0 0 0">
                                            <geom name="lmetafour2lproxfour" type="capsule" fromto="0 0 0 0 0.0578554 0" size="0.0075"/>
                                            <joint name="lh_4_meta" type="hinge" pos="0 0 0" axis="1 0 0" range="-1.570796 -0.01" damping="5" stiffness="50" armature="0.02"/>
                                                <body name="lh_prox_4" pos="0 0.0578554 0" euler="0 0 0">
                                                    <geom name="lproxfour2lmedfour" type="capsule" fromto="0 0 0 0 0.0495246 0" size="0.0075"/>
                                                    <joint name="lh_4_prox" type="hinge" pos="0 0 0" axis="1 0 0" range="-1.570796 -0.01" damping="5" stiffness="50" armature="0.02"/>
                                                        <body name="lh_med_4" pos="0 0.0495246 0" euler="0 0 0">
                                                            <geom name="lmedfour2ldistfour" type="capsule" fromto="0 0 0 0 0.0226809 0" size="0.0075"/>
                                                            <joint name="lh_4_med" type="hinge" pos="0 0 0" axis="1 0 0" range="-1.570796 -0.01" damping="5" stiffness="50" armature="0.02"/> 
                                                                <body name="lh_dist_4" pos="0 0.0226809 0" euler="0 0 0"/>
                                                        </body>
                                                </body>
                                        </body>
                                        <body name="lh_meta_5" pos="-0.023199 0.0339833 -0.0007049" euler="0 0 0">
                                            <geom name="lmetafive2lproxfive" type="capsule" fromto="0 0 0 0 0.0542941 0" size="0.0075"/>
                                            <joint name="lh_5_meta" type="hinge" pos="0 0 0" axis="1 0 0" range="-1.570796 -0.01" damping="5" stiffness="50" armature="0.02"/>
                                                <body name="lh_prox_5" pos="0 0.0542941 0" euler="0 0 0">
                                                    <geom name="lproxfive2lmedfive" type="capsule" fromto="0 0 0 0 0.0350421 0" size="0.0075"/>
                                                    <joint name="lh_5_prox" type="hinge" pos="0 0 0" axis="1 0 0" range="-1.570796 -0.01" damping="5" stiffness="50" armature="0.02"/>
                                                        <body name="lh_med_5" pos="0 0.0350421 0" euler="0 0 0">
                                                            <geom name="lmedfive2ldistfive" type="capsule" fromto="0 0 0 0 0.0211006 0" size="0.0075"/>
                                                            <joint name="lh_5_med" type="hinge" pos="0 0 0" axis="1 0 0" range="-1.570796 -0.01" damping="5" stiffness="50" armature="0.02"/> 
                                                                <body name="lh_dist_5" pos="0 0.0211006 0" euler="0 0 0"/>
                                                        </body>
                                                </body>
                                        </body>
                                    </body>
                                </body>
                            </body>
                        </body>
                        <body name="head" pos="0 0 0.1817364" euler="0 0 0">
                            <geom name="head" type="box" pos="0 0 0" size="0.06 0.06 0.07" />
                            <geom name="nose" type="box" pos="0.05 0 0" size="0.05 0.02 0.02" />
                            <joint name="head1" type="hinge" pos="0 0 0" axis="1 0 0" range="-1.57 1.57" damping="5" stiffness="50" armature="0.02" />
                            <joint name="head2" type="hinge" pos="0 0 0" axis="0 1 0" range="-1.57 1.57" damping="5" stiffness="50" armature="0.02" />
                            <joint name="head3" type="hinge" pos="0 0 0" axis="0 0 1" range="-1.57 1.57" damping="5" stiffness="50" armature="0.02" />
                        </body>
                    </body>
                </body>
            </body>
            <body name="right_leg" pos="0 0 0" euler="0 0 0">
                <geom name="base2rpelvis" type="capsule" fromto="0 0 0 0 -0.100371 0"  size="0.035" />
                <body name="right_pelvis" pos="0 -0.100371 0" euler="0 0 0">
                    <geom name="rpelvis2rknee" type="capsule" fromto="0 0 0 -0.013579 0.00242305 -0.445198"  size="0.035" />
                    <joint name="rp1" type="hinge" pos="0 0 0" axis="1 0 0" range="-1.57 0.785" damping="30" stiffness="900" armature="0.01" />
                    <joint name="rp2" type="hinge" pos="0 0 0" axis="0 1 0" range="-3.141592 2.267778" damping="30" stiffness="900" armature="0.01" />
                    <joint name="rp3" type="hinge" pos="0 0 0" axis="0 0 1" range="-0.52333333333 0.52333333333" damping="30" stiffness="900" armature="0.01" />
                    <body name="right_knee" pos="-0.013579 0.00242305 -0.445198" euler="0 0 0">
                        <geom name="rknee2rankle" type="capsule" fromto="0 0 0 0 0 -0.436307"  size="0.035" />
                        <joint name="rk" type="hinge" pos="0 0 0" axis="0 1 0" range="0.0175 2.0944" damping="30" stiffness="900" armature="0.0060" />
                        <body name="right_ankle" pos="0 0 -0.436307" euler="0 0 0">
                            <geom name="rankle" type="box" pos="0 0 -0.025" size="0.03 0.03 0.025" />
                            <geom name="rfoot" type="box" pos="0.03 0 -0.05" size="0.1 0.05 0.015" />
                            <joint name="ra1" type="hinge" pos="0 0 0" axis="0 1 0" range="-1.57 0.697778" stiffness="600" damping="20" armature="0.0008" />
                            <joint name="ra2" type="hinge" pos="0 0 0" axis="1 0 0" range="-0.261667 0.261667" stiffness="600" damping="20" armature="0.0006" />
                            <joint name="ra3" type="hinge" pos="0 0 0" axis="0 0 1" range="-0.52333333333 0.52333333333" stiffness="600" damping="20" armature="0.0006" />
                        </body>
                    </body>
                </body>
            </body>
            <body name="left_leg" pos="0 0 0" euler="0 0 0">
                <geom name="base2lpelvis" type="capsule" fromto="0 0 0 0 0.100371 0"  size="0.035" />
                <body name="left_pelvis" pos="0 0.100371 0" euler="0 0 0">
                    <geom name="lpelvis2lknee" type="capsule" fromto="0 0 0 -0.013579 -0.00242347 -0.445198"  size="0.035" />
                    <joint name="lp1" type="hinge" pos="0 0 0" axis="1 0 0" range="-0.785 1.57" damping="30" stiffness="900" armature="0.01" />
                    <joint name="lp2" type="hinge" pos="0 0 0" axis="0 1 0" range="-3.141592 2.267778" damping="30" stiffness="900" armature="0.01" />
                    <joint name="lp3" type="hinge" pos="0 0 0" axis="0 0 1" range="-0.52333333333 0.52333333333" damping="30" stiffness="900" armature="0.01" />
                    <body name="left_knee" pos="-0.013579 -0.00242347 -0.445198" euler="0 0 0">
                        <geom name="lknee2lankle" type="capsule" fromto="0 0 0 0 0 -0.436307"  size="0.035" />
                        <joint name="lk" type="hinge" pos="0 0 0" axis="0 1 0" range="0.0175 2.0944" damping="30" stiffness="900" armature="0.0060" />
                        <body name="left_ankle" pos="0 0 -0.436307" euler="0 0 0">
                            <geom name="lankle" type="box" pos="0 0 -0.025" size="0.03 0.03 0.025" />
                            <geom name="lfoot" type="box" pos="0.03 0 -0.05" size="0.1 0.05 0.015" />
                            <joint name="la1" type="hinge" pos="0 0 0" axis="0 1 0" range="-1.57 0.697778" stiffness="600" damping="20" armature="0.0008" />
                            <joint name="la2" type="hinge" pos="0 0 0" axis="1 0 0" range="-0.261667 0.261667" stiffness="600" damping="20" armature="0.0006" />
                            <joint name="la3" type="hinge" pos="0 0 0" axis="0 0 1" range="-0.52333333333 0.52333333333" stiffness="600" damping="20" armature="0.0006" />
                        </body>
                    </body>
                </body>
            </body>
        </body>
    </worldbody>

    <!-- <equality>
        <joint name='rh_1_21' joint1="rh_1_prox" joint2="rh_1_meta" polycoef="0 1 0 0 0"/>
        <joint name='rh_1_32' joint1="rh_1_dist" joint2="rh_1_prox" polycoef="0 1 0 0 0"/>
        <joint name='rh_2_21' joint1="rh_2_med" joint2="rh_2_prox" polycoef="0 3 0 0 0"/>
        <joint name='rh_2_32' joint1="rh_2_dist" joint2="rh_2_med" polycoef="0 0.6666 0 0 0"/>
        <joint name='rh_3_21' joint1="rh_3_med" joint2="rh_3_prox" polycoef="0 3 0 0 0"/>
        <joint name='rh_3_32' joint1="rh_3_dist" joint2="rh_3_med" polycoef="0 0.6666 0 0 0"/>
        <joint name='rh_4_21' joint1="rh_4_med" joint2="rh_4_prox" polycoef="0 3 0 0 0"/>
        <joint name='rh_4_32' joint1="rh_4_dist" joint2="rh_4_med" polycoef="0 0.6666 0 0 0"/>
        <joint name='rh_5_21' joint1="rh_5_med" joint2="rh_5_prox" polycoef="0 3 0 0 0"/>
        <joint name='rh_5_32' joint1="rh_5_dist" joint2="rh_5_med" polycoef="0 0.6666 0 0 0"/>

        <joint name='lh_1_21' joint1="lh_1_prox" joint2="lh_1_meta" polycoef="0 1 0 0 0"/>
        <joint name='lh_1_32' joint1="lh_1_dist" joint2="lh_1_prox" polycoef="0 1 0 0 0"/>
        <joint name='lh_2_21' joint1="lh_2_med" joint2="lh_2_prox" polycoef="0 3 0 0 0"/>
        <joint name='lh_2_32' joint1="lh_2_dist" joint2="lh_2_med" polycoef="0 0.6666 0 0 0"/>
        <joint name='lh_3_21' joint1="lh_3_med" joint2="lh_3_prox" polycoef="0 3 0 0 0"/>
        <joint name='lh_3_32' joint1="lh_3_dist" joint2="lh_3_med" polycoef="0 0.6666 0 0 0"/>
        <joint name='lh_4_21' joint1="lh_4_med" joint2="lh_4_prox" polycoef="0 3 0 0 0"/>
        <joint name='lh_4_32' joint1="lh_4_dist" joint2="lh_4_med" polycoef="0 0.6666 0 0 0"/>
        <joint name='lh_5_21' joint1="lh_5_med" joint2="lh_5_prox" polycoef="0 3 0 0 0"/>
        <joint name='lh_5_32' joint1="lh_5_dist" joint2="lh_5_med" polycoef="0 0.6666 0 0 0"/>
    </equality> -->

    <actuator>
        <!-- [1] ~ [4] -->
        <motor name="root1"       gear="200" joint="root1" />
        <motor name="root2"       gear="200" joint="root2" />
        <motor name="root3"       gear="200" joint="root3" />
        <motor name="spine"       gear="200" joint="spine" />
        <!-- [5] ~ [11] -->
        <motor name="rs1"         gear="100" joint="rs1" />
        <motor name="rs2"         gear="100" joint="rs2" />
        <motor name="rs3"         gear="100" joint="rs3" />
        <motor name="re"          gear="200" joint="re" />
        <motor name="rw1"         gear="100" joint="rw1" />
        <motor name="rw2"         gear="100" joint="rw2" />
        <motor name="rw3"         gear="100" joint="rw3" />
        <!-- [12] ~ [18] -->
        <motor name="ls1"         gear="100" joint="ls1" />
        <motor name="ls2"         gear="100" joint="ls2" />
        <motor name="ls3"         gear="100" joint="ls3" />
        <motor name="le"          gear="200" joint="le" />
        <motor name="lw1"         gear="100" joint="lw1" />
        <motor name="lw2"         gear="100" joint="lw2" />
        <motor name="lw3"         gear="100" joint="lw3" />
        <!-- [19] ~ [25] -->
        <motor name="rp1"         gear="600" joint="rp1" />
        <motor name="rp2"         gear="200" joint="rp2" />
        <motor name="rp3"         gear="200" joint="rp3" />
        <motor name="rk"          gear="400" joint="rk" />
        <motor name="ra1"         gear="100" joint="ra1" />
        <motor name="ra2"         gear="100" joint="ra2" />
        <motor name="ra3"         gear="100" joint="ra3" />
        <!-- [26] ~ [32] -->
        <motor name="lp1"         gear="600" joint="lp1" />
        <motor name="lp2"         gear="200" joint="lp2" />
        <motor name="lp3"         gear="200" joint="lp3" />
        <motor name="lk"          gear="400" joint="lk" />
        <motor name="la1"         gear="100" joint="la1" />
        <motor name="la2"         gear="100" joint="la2" />
        <motor name="la3"         gear="100" joint="la3" />
        <!-- [33] ~ [35] -->
        <motor name="head1"       gear="200" joint="head1" />
        <motor name="head2"       gear="200" joint="head2" />
        <motor name="head3"       gear="200" joint="head3" />

        <motor name="rc"         gear="100" joint="rc" />
        <motor name="lc"         gear="100" joint="lc" />

        <!-- right hand -->
        <!-- <position name="rh_1_abd"   class="hand"  joint="rh_1_abd"   ctrlrange="0 90"/> -->
        <position name="rh_1_meta"  class="hand"  joint="rh_1_meta"  ctrlrange="0 180"/>
        <position name="rh_2_abd"   class="hand"  joint="rh_2_abd"   ctrlrange="0 180"/>
        <position name="rh_2_prox"  class="hand"  joint="rh_2_prox"  ctrlrange="0 180"/>
        <position name="rh_3_prox"  class="hand"  joint="rh_3_prox"  ctrlrange="0 180"/>
        <position name="rh_4_prox"  class="hand"  joint="rh_4_prox"  ctrlrange="0 180"/>
        <position name="rh_5_prox"  class="hand"  joint="rh_5_prox"  ctrlrange="0 180"/>

        <!-- left hand -->
        <!-- <position name="lh_1_abd"   class="hand"  joint="lh_1_abd" ctrlrange="-90 0"/> -->
        <position name="lh_1_meta"  class="hand"  joint="lh_1_meta"  ctrlrange="-180 0"/>
        <position name="lh_2_abd"   class="hand"  joint="lh_2_abd"   ctrlrange="-180 0"/>
        <position name="lh_2_prox"  class="hand"  joint="lh_2_prox"  ctrlrange="-180 0"/>
        <position name="lh_3_prox"  class="hand"  joint="lh_3_prox"  ctrlrange="-180 0"/>
        <position name="lh_4_prox"  class="hand"  joint="lh_4_prox"  ctrlrange="-180 0"/>
        <position name="lh_5_prox"  class="hand"  joint="lh_5_prox"  ctrlrange="-180 0"/>

    </actuator>

    <!-- exclude -->
    <contact>
        <exclude body1="neck" body2="right_shoulder"/>
        <exclude body1="spine" body2="right_shoulder"/>
        <exclude body1="right_shoulder" body2="right_elbow"/>
        <exclude body1="right_elbow" body2="right_wrist"/>

        <exclude body1="neck" body2="left_shoulder"/>
        <exclude body1="spine" body2="left_shoulder"/>
        <exclude body1="left_shoulder" body2="left_elbow"/>
        <exclude body1="left_elbow" body2="left_wrist"/>

        <exclude body1="neck" body2="spine"/>
        <exclude body1="spine" body2="torso"/>
        <exclude body1="torso" body2="base"/>

        <exclude body1="torso" body2="right_pelvis"/>
        <exclude body1="right_leg" body2="base"/>
        <exclude body1="right_leg" body2="torso"/>
        <exclude body1="right_leg" body2="right_pelvis"/>
        <exclude body1="right_pelvis" body2="right_knee"/>
        <exclude body1="right_knee" body2="right_ankle"/>

        <exclude body1="right_leg" body2="left_leg"/>

        <exclude body1="torso" body2="left_pelvis"/>
        <exclude body1="left_leg" body2="base"/>
        <exclude body1="left_leg" body2="torso"/>
        <exclude body1="left_leg" body2="left_pelvis"/>
        <exclude body1="left_pelvis" body2="left_knee"/>
        <exclude body1="left_knee" body2="left_ankle"/>

        <exclude body1="right_elbow" body2="rh_meta_1"/>
        <exclude body1="right_elbow" body2="rh_meta_2"/>
        <exclude body1="right_elbow" body2="rh_prox_3"/>

        <exclude body1="right_wrist" body2="rh_meta_2"/>
        <exclude body1="right_wrist" body2="rh_meta_3"/>
        <exclude body1="right_wrist" body2="rh_meta_4"/>
        <exclude body1="right_wrist" body2="rh_meta_5"/>
        <exclude body1="rh_meta_2" body2="rh_meta_1"/>

        <exclude body1="rh_meta_1" body2="rh_prox_1"/>
        <exclude body1="rh_prox_1" body2="rh_dist_1"/>
        
        <exclude body1="rh_meta_2" body2="rh_prox_2"/>
        <exclude body1="rh_prox_2" body2="rh_med_2"/>
        <exclude body1="rh_med_2" body2="rh_dist_2"/>

        <exclude body1="rh_meta_3" body2="rh_prox_3"/>
        <exclude body1="rh_prox_3" body2="rh_med_3"/>
        <exclude body1="rh_med_3" body2="rh_dist_3"/>

        <exclude body1="rh_meta_4" body2="rh_prox_4"/>
        <exclude body1="rh_prox_4" body2="rh_med_4"/>
        <exclude body1="rh_med_4" body2="rh_dist_4"/>

        <exclude body1="rh_meta_5" body2="rh_prox_5"/>
        <exclude body1="rh_prox_5" body2="rh_med_5"/>
        <exclude body1="rh_med_5" body2="rh_dist_5"/>

        <exclude body1="left_elbow" body2="lh_meta_1"/>
        <exclude body1="left_elbow" body2="lh_meta_2"/>
        <exclude body1="left_elbow" body2="lh_prox_3"/>

        <exclude body1="left_wrist" body2="lh_meta_2"/>
        <exclude body1="left_wrist" body2="lh_meta_3"/>
        <exclude body1="left_wrist" body2="lh_meta_4"/>
        <exclude body1="left_wrist" body2="lh_meta_5"/>
        <exclude body1="lh_meta_2" body2="lh_meta_1"/>

        <exclude body1="lh_meta_1" body2="lh_prox_1"/>
        <exclude body1="lh_prox_1" body2="lh_dist_1"/>

        <exclude body1="lh_meta_2" body2="lh_prox_2"/>
        <exclude body1="lh_prox_2" body2="lh_med_2"/>
        <exclude body1="lh_med_2" body2="lh_dist_2"/>

        <exclude body1="lh_meta_3" body2="lh_prox_3"/>
        <exclude body1="lh_prox_3" body2="lh_med_3"/>
        <exclude body1="lh_med_3" body2="lh_dist_3"/>

        <exclude body1="lh_meta_4" body2="lh_prox_4"/>
        <exclude body1="lh_prox_4" body2="lh_med_4"/>
        <exclude body1="lh_med_4" body2="lh_dist_4"/>

        <exclude body1="lh_meta_5" body2="lh_prox_5"/>
        <exclude body1="lh_prox_5" body2="lh_med_5"/>
        <exclude body1="lh_med_5" body2="lh_dist_5"/>
    </contact>


</mujoco>
